<?xml version="1.0" encoding="utf-8"?>

<robot
  name="Chimuelo">
  <link
    name="base_link">
    <inertial>
      <origin
        xyz="-0.086556517332142 -0.000352727645888733 0.145442331034338"
        rpy="0 0 0" />
      <mass
        value="3.05772209092401" />
      <inertia
        ixx="0.0217470372399453"
        ixy="-1.05321426778705E-09"
        ixz="0.000948701046615053"
        iyy="0.0265069257409422"
        iyz="4.99589261433505E-10"
        izz="0.0358779431111827" />
    </inertial>
    <visual>
      <origin
        xyz="0 0 0"
        rpy="0 0 0" />
      <geometry>
        <mesh
          filename="package://robot2_description/meshes/meshes/base_link2.STL" />
      </geometry>
      <material
        name="">
        <color
          rgba="0.694117647058824 0.0980392156862745 0.0980392156862745 1" />
      </material>
    </visual>
    <collision>
      <origin
        xyz="0 0 0"
        rpy="0 0 0" />
      <geometry>
        <mesh
          filename="package://robot2_description/meshes/meshes/base_link.STL" />
      </geometry>
    </collision>
  </link>
  <link
    name="wheel_1">
    <inertial>
      <origin
        xyz="4.28687863474053E-06 2.56655050152529E-05 0.00456180317344754"
        rpy="0 0 0" />
      <mass
        value="2.14238895060809" />
      <inertia
        ixx="0.00326996983425982"
        ixy="1.41634129644213E-07"
        ixz="-8.57942178102723E-07"
        iyy="0.00326974873935524"
        iyz="1.26652385740975E-06"
        izz="0.00576798292282185" />
    </inertial>
    <visual>
      <origin
        xyz="0 0 0"
        rpy="0 0 0" />
      <geometry>
        <mesh
          filename="package://robot2_description/meshes/meshes/wheel_1.STL" />
      </geometry>
      <material
        name="">
        <color
          rgba="0.752941176470588 0.752941176470588 0.752941176470588 1" />
      </material>
    </visual>
    <collision>
      <origin
        xyz="0 0 0"
        rpy="0 0 0" />
      <geometry>
        <mesh
          filename="package://robot2_description/meshes/meshes/wheel_1.STL" />
      </geometry>
    </collision>
  </link>
  <joint
    name="base_to_wheel1"
    type="continuous">
    <origin
      xyz="0.268596813272053 0.221947346984468 -0.0238912873621778"
      rpy="-1.5707963267949 0.0469290720831621 0" />
    <parent
      link="base_link" />
    <child
      link="wheel_1" />
    <axis
      xyz="0 0 1" />
  </joint>
  <link
    name="wheel_2">
    <inertial>
      <origin
        xyz="2.53096910307615E-05 -6.04251910264753E-06 0.00456180318511781"
        rpy="0 0 0" />
      <mass
        value="2.14238894711852" />
      <inertia
        ixx="0.00326973032836068"
        ixy="-1.25121641120556E-07"
        ixz="1.32255241239349E-06"
        iyy="0.00326998822971707"
        iyz="7.68767301483412E-07"
        izz="0.00576798290759503" />
    </inertial>
    <visual>
      <origin
        xyz="0 0 0"
        rpy="0 0 0" />
      <geometry>
        <mesh
          filename="package://robot2_description/meshes/meshes/wheel_2.STL" />
      </geometry>
      <material
        name="">
        <color
          rgba="0.752941176470588 0.752941176470588 0.752941176470588 1" />
      </material>
    </visual>
    <collision>
      <origin
        xyz="0 0 0"
        rpy="0 0 0" />
      <geometry>
        <mesh
          filename="package://robot2_description/meshes/meshes/wheel_2.STL" />
      </geometry>
    </collision>
  </link>
  <joint
    name="base_to_wheel2"
    type="continuous">
    <origin
      xyz="-0.290849540181399 0.221947346984467 0.0155522403587198"
      rpy="-1.5707963267949 0.0469290720831621 0" />
    <parent
      link="base_link" />
    <child
      link="wheel_2" />
    <axis
      xyz="0 0 1" />
  </joint>
  <link
    name="wheel_3">
    <inertial>
      <origin
        xyz="-2.5929216212417E-05 2.184238061885E-06 0.0045618049274439"
        rpy="0 0 0" />
      <mass
        value="2.14238895012168" />
      <inertia
        ixx="0.00326977317552177"
        ixy="-1.57690109692095E-07"
        ixz="-1.19251285936122E-06"
        iyy="0.0032699453965459"
        iyz="-9.58154725423105E-07"
        izz="0.00576798292142971" />
    </inertial>
    <visual>
      <origin
        xyz="0 0 0"
        rpy="0 0 0" />
      <geometry>
        <mesh
          filename="package://robot2_description/meshes/meshes/wheel_3.STL" />
      </geometry>
      <material
        name="">
        <color
          rgba="0.752941176470588 0.752941176470588 0.752941176470588 1" />
      </material>
    </visual>
    <collision>
      <origin
        xyz="0 0 0"
        rpy="0 0 0" />
      <geometry>
        <mesh
          filename="package://robot2_description/meshes/meshes/wheel_3.STL" />
      </geometry>
    </collision>
  </link>
  <joint
    name="base_to_wheel3"
    type="continuous">
    <origin
      xyz="0.268596813272053 -0.222652653015534 -0.0238912873621771"
      rpy="1.5707963267949 0.0469290720831621 0" />
    <parent
      link="base_link" />
    <child
      link="wheel_3" />
    <axis
      xyz="0 0 1" />
  </joint>
  <link
    name="wheel_4">
    <inertial>
      <origin
        xyz="1.54168347321626E-06 -2.59753479063124E-05 0.0045618049269881"
        rpy="0 0 0" />
      <mass
        value="2.14238895030598" />
      <inertia
        ixx="0.00326989729898636"
        ixy="1.75601819728279E-07"
        ixz="1.11866010310357E-06"
        iyy="0.00326982127473219"
        iyz="-1.04343030818665E-06"
        izz="0.0057679829229971" />
    </inertial>
    <visual>
      <origin
        xyz="0 0 0"
        rpy="0 0 0" />
      <geometry>
        <mesh
          filename="package://robot2_description/meshes/meshes/wheel_4.STL" />
      </geometry>
      <material
        name="">
        <color
          rgba="0.752941176470588 0.752941176470588 0.752941176470588 1" />
      </material>
    </visual>
    <collision>
      <origin
        xyz="0 0 0"
        rpy="0 0 0" />
      <geometry>
        <mesh
          filename="package://robot2_description/meshes/meshes/wheel_4.STL" />
      </geometry>
    </collision>
  </link>
  <joint
    name="base_to_wheel4"
    type="continuous">
    <origin
      xyz="-0.2908495401814 -0.222652653015533 0.0155522403587205"
      rpy="1.5707963267949 0.0469290720831621 0" />
    <parent
      link="base_link" />
    <child
      link="wheel_4" />
    <axis
      xyz="0 0 1" />
  </joint>
  <link
    name="camera_Link">
    <inertial>
      <origin
        xyz="-0.0127423380440134 -3.31030078943769E-05 -5.50915431430932E-05"
        rpy="0 0 0" />
      <mass
        value="0.0482487786070299" />
      <inertia
        ixx="2.7379683231221E-05"
        ixy="-4.24685040804238E-07"
        ixz="-7.38178395287798E-09"
        iyy="3.37552517038898E-06"
        iyz="-1.09088263505779E-08"
        izz="2.66336069877703E-05" />
    </inertial>
    <visual>
      <origin
        xyz="0 0 0"
        rpy="0 0 0" />
      <geometry>
        <mesh
          filename="package://robot2_description/meshes/meshes/camera_Link.STL" />
      </geometry>
      <material
        name="">
        <color
          rgba="0.776470588235294 0.756862745098039 0.737254901960784 1" />
      </material>
    </visual>
    <collision>
      <origin
        xyz="0 0 0"
        rpy="0 0 0" />
      <geometry>
        <mesh
          filename="package://robot2_description/meshes/meshes/camera_Link.STL" />
      </geometry>
    </collision>
  </link>
  <joint
    name="joint_camera"
    type="fixed">
    <origin
      xyz="0.214974883978717 0 0.109787250365629"
      rpy="0 0 0" />
    <parent
      link="base_link" />
    <child
      link="camera_Link" />
    <axis
      xyz="0 0 0" />
  </joint>
  <link
    name="display_Link">
    <inertial>
      <origin
        xyz="0.000595607428620907 -0.00166882370174587 0.00205429705023452"
        rpy="0 0 0" />
      <mass
        value="0.10709440739256" />
      <inertia
        ixx="9.4101902791338E-05"
        ixy="-7.40473992221205E-08"
        ixz="-7.22767416521283E-09"
        iyy="0.000261159419467855"
        iyz="-1.8038582813121E-05"
        izz="0.000347264298444477" />
    </inertial>
    <visual>
      <origin
        xyz="0 0 0"
        rpy="0 0 0" />
      <geometry>
        <mesh
          filename="package://robot2_description/meshes/meshes/display_Link.STL" />
      </geometry>
      <material
        name="">
        <color
          rgba="0.792156862745098 0.819607843137255 0.933333333333333 1" />
      </material>
    </visual>
    <collision>
      <origin
        xyz="0 0 0"
        rpy="0 0 0" />
      <geometry>
        <mesh
          filename="package://robot2_description/meshes/meshes/display_Link.STL" />
      </geometry>
    </collision>
  </link>
  <joint
    name="joint_display"
    type="fixed">
    <origin
      xyz="0.102857942049151 0.000258187050887984 0.162423318741253"
      rpy="2.2099764684662 0 -1.5707963267949" />
    <parent
      link="base_link" />
    <child
      link="display_Link" />
    <axis
      xyz="0 0 0" />
  </joint>
  <link
    name="Lidar_Link">
    <inertial>
      <origin
        xyz="0.000612709154446269 0.00363709317194675 -0.0358143411665422"
        rpy="0 0 0" />
      <mass
        value="0.615914242692759" />
      <inertia
        ixx="0.000690610915413377"
        ixy="3.88041044561775E-09"
        ixz="-3.80091276246756E-08"
        iyy="0.000685830785416164"
        iyz="-1.79890178853214E-05"
        izz="0.000837102685248035" />
    </inertial>
    <visual>
      <origin
        xyz="0 0 0"
        rpy="0 0 0" />
      <geometry>
        <mesh
          filename="package://robot2_description/meshes/meshes/Lidar_Link.STL" />
      </geometry>
      <material
        name="">
        <color
          rgba="0.952941176470588 0.996078431372549 0.694117647058824 1" />
      </material>
    </visual>
    <collision>
      <origin
        xyz="0 0 0"
        rpy="0 0 0" />
      <geometry>
        <mesh
          filename="package://robot2_description/meshes/meshes/Lidar_Link.STL" />
      </geometry>
    </collision>
  </link>
  <joint
    name="joint_lidar"
    type="fixed">
    <origin
      xyz="0.00866580183122841 0.000258187050887935 0.242539468975184"
      rpy="3.04651840513953 0 -1.5707963267949" />
    <parent
      link="base_link" />
    <child
      link="Lidar_Link" />
    <axis
      xyz="0 0 0" />
  </joint>
  <link
    name="jetson_Link">
    <inertial>
      <origin
        xyz="-0.0580393674464423 0.0129275260649628 -0.0125466332986841"
        rpy="0 0 0" />
      <mass
        value="0.0920287361873364" />
      <inertia
        ixx="8.50116016168317E-05"
        ixy="1.75431492706041E-06"
        ixz="-2.11664110509791E-07"
        iyy="7.12593040947099E-05"
        iyz="-1.12587757341161E-07"
        izz="0.000151485866464735" />
    </inertial>
    <visual>
      <origin
        xyz="0 0 0"
        rpy="0 0 0" />
      <geometry>
        <mesh
          filename="package://robot2_description/meshes/meshes/jetson_Link.STL" />
      </geometry>
      <material
        name="">
        <color
          rgba="0.752941176470588 0.752941176470588 0.752941176470588 1" />
      </material>
    </visual>
    <collision>
      <origin
        xyz="0 0 0"
        rpy="0 0 0" />
      <geometry>
        <mesh
          filename="package://robot2_description/meshes/meshes/jetson_Link.STL" />
      </geometry>
    </collision>
  </link>
  <joint
    name="joint_jetson"
    type="fixed">
    <origin
      xyz="-0.06900655266613 -0.0648624918126707 0.0766510267295609"
      rpy="-1.71042266695444 0 -1.5707963267949" />
    <parent
      link="base_link" />
    <child
      link="jetson_Link" />
    <axis
      xyz="0 0 0" />
  </joint>
  <link
    name="camera2_Link">
    <inertial>
      <origin
        xyz="-0.0127423398321038 3.30950237478823E-05 5.50944238715267E-05"
        rpy="0 0 0" />
      <mass
        value="0.0482487661118923" />
      <inertia
        ixx="2.73796549883854E-05"
        ixy="4.24682419134219E-07"
        ixz="7.38231172288537E-09"
        iyy="3.37552550649944E-06"
        iyz="-1.09072827757756E-08"
        izz="2.66335777639077E-05" />
    </inertial>
    <visual>
      <origin
        xyz="0 0 0"
        rpy="0 0 0" />
      <geometry>
        <mesh
          filename="package://robot2_description/meshes/meshes/camera2_Link.STL" />
      </geometry>
      <material
        name="">
        <color
          rgba="0.776470588235294 0.756862745098039 0.737254901960784 1" />
      </material>
    </visual>
    <collision>
      <origin
        xyz="0 0 0"
        rpy="0 0 0" />
      <geometry>
        <mesh
          filename="package://robot2_description/meshes/meshes/camera2_Link.STL" />
      </geometry>
    </collision>
  </link>
  <joint
    name="joint_camera2"
    type="fixed">
    <origin
      xyz="-0.248514994181185 0 0.218074476154433"
      rpy="0 0.103752019865341 -3.14159265358979" />
    <parent
      link="base_link" />
    <child
      link="camera2_Link" />
    <axis
      xyz="0 0 0" />
  </joint>
</robot>
